Workbook
Name FechaFiesta: Inicio!$B$6
Name InvitadosPrevistos: Inicio!$B$11
Name PresupuestoTotal: Inicio!$B$12
Name PorcentajeReserva: Inicio!$B$14
Name PersonasConfirmadas: Inicio!$E$6

Sheet Inicio
A1: Plan de la fiesta de boda
A2: Llena las celdas claras. Los totales salen solos. Si aparecen invitados, son cuatro filas de ejemplo: bórralas en Invitados.
A4: Datos de la fiesta | D4: Invitados y avance | G4: Presupuesto
A5: Pareja | D5: En la lista | E5: =SUM(Invitados!I8:I107) | G5: Presupuesto | H5: =B12
A6: Fecha de la fiesta | D6: Confirmadas | E6: =SUMIF(Invitados!K8:K107,"Confirmado",Invitados!I8:I107) | G6: Conceptos | H6: =Presupuesto!G54
A7: Ciudad | D7: Sin respuesta | E7: =SUMIF(Invitados!K8:K107,"Pendiente",Invitados!I8:I107) | G7: =IF(B14="","Reserva","Reserva ("&TEXT(B14,"0%")&")") | H7: =IF(B12="","",B12*IF(B14="",0,B14))
A8: Lugar de la ceremonia | D8: No asisten | E8: =SUMIF(Invitados!K8:K107,"Rechazado",Invitados!I8:I107) | G8: Estimado con reserva | H8: =N(H6)+N(H7)
A9: Lugar de la recepción | D9: Tareas | G9: Pagado | H9: =Presupuesto!I54
A10: Hora de inicio | D10: Tareas hechas | E10: =IF(COUNTA(Tareas!B8:B49)=0,"",COUNTIF(Tareas!G8:G49,"Hecho")&" de "&COUNTA(Tareas!B8:B49)) | G10: Por pagar | H10: =Presupuesto!J54
A11: Invitados previstos | D11: Avance | E11: =IF(COUNTA(Tareas!B8:B49)=0,"",COUNTIF(Tareas!G8:G49,"Hecho")/COUNTA(Tareas!B8:B49)) | G11: Disponible | H11: =IF(B12="","",B12-N(H8))
A12: Presupuesto total | D12: Días restantes | E12: =IF(B6="","",B6-TODAY()) | G12: Por persona, sin reserva | H12: =IF(OR(B11="",B11=0,H6=0),"",H6/B11)
A13: Moneda | B13: MXN | G13: Estado | H13: =IF(B12="","Falta el presupuesto",IF(H8>B12,"Por encima del presupuesto",IF(H8>=B12*0.9,"Cerca del límite","Dentro del presupuesto")))
A14: Reserva para imprevistos | B14: 0.1
A15: Persona para imprevistos
A16: Teléfono de esa persona | D16: =IF(E5=0,"",IF(E5=E6+E7+E8,"La lista cuadra","Revisa filas sin RSVP o sin número de personas"))
G17: =IF(B13="","","Montos en "&B13)
A38: Fuente: hoja Presupuesto. El estimado incluye la reserva para imprevistos. Pagado es lo registrado en cada concepto, sin contar la reserva.

Sheet Presupuesto
A1: Presupuesto
A2: Escribe costos en las celdas claras. Si el gasto es por persona y Ajuste está vacío, la cantidad son los invitados previstos. El saldo usa Contratado; si está vacío, usa el estimado.
A4: Conceptos | C4: =G54 | E4: Contratado | G4: =H54 | I4: Pagado | K4: =I54
A5: Saldo de conceptos | C5: =J54 | E5: Reserva | G5: =Inicio!H7 | I5: Estimado con reserva | K5: =N(G54)+N(Inicio!H7)
O6: Resumen por categoría
A7: Categoría | B7: Concepto | C7: Por persona | D7: Ajuste | E7: Cantidad | F7: Costo unitario | G7: Estimado | H7: Contratado | I7: Pagado | J7: Saldo | K7: Estado | L7: Fecha de pago | M7: Notas | O7: Categoría | P7: Estimado | Q7: % del presupuesto | R7: Pagado
A8: Lugar | B8: Renta del salón o jardín | C8: No | E8: =IF(D8<>"",D8,IF(C8="Sí",IF(InvitadosPrevistos="", "",InvitadosPrevistos),"")) | G8: =IF(OR(E8="",F8=""),"",E8*F8) | J8: =IF(AND(G8="",H8="",I8=""),"",IF(H8="",N(G8),N(H8))-N(I8)) | O8: Lugar | P8: =SUMIF($A$8:$A$53,O8,$G$8:$G$53) | Q8: =IF(OR(PresupuestoTotal="",PresupuestoTotal=0),"",P8/PresupuestoTotal) | R8: =SUMIF($A$8:$A$53,O8,$I$8:$I$53)
A9: Lugar | B9: Hora extra | C9: No | E9: =IF(D9<>"",D9,IF(C9="Sí",IF(InvitadosPrevistos="", "",InvitadosPrevistos),"")) | G9: =IF(OR(E9="",F9=""),"",E9*F9) | J9: =IF(AND(G9="",H9="",I9=""),"",IF(H9="",N(G9),N(H9))-N(I9)) | O9: Banquete | P9: =SUMIF($A$8:$A$53,O9,$G$8:$G$53) | Q9: =IF(OR(PresupuestoTotal="",PresupuestoTotal=0),"",P9/PresupuestoTotal) | R9: =SUMIF($A$8:$A$53,O9,$I$8:$I$53)
A10: Lugar | B10: Permiso o cargo del lugar | C10: No | E10: =IF(D10<>"",D10,IF(C10="Sí",IF(InvitadosPrevistos="", "",InvitadosPrevistos),"")) | G10: =IF(OR(E10="",F10=""),"",E10*F10) | J10: =IF(AND(G10="",H10="",I10=""),"",IF(H10="",N(G10),N(H10))-N(I10)) | O10: Bebidas | P10: =SUMIF($A$8:$A$53,O10,$G$8:$G$53) | Q10: =IF(OR(PresupuestoTotal="",PresupuestoTotal=0),"",P10/PresupuestoTotal) | R10: =SUMIF($A$8:$A$53,O10,$I$8:$I$53)
A11: Banquete | B11: Alimentos por persona | C11: Sí | E11: =IF(D11<>"",D11,IF(C11="Sí",IF(InvitadosPrevistos="", "",InvitadosPrevistos),"")) | G11: =IF(OR(E11="",F11=""),"",E11*F11) | J11: =IF(AND(G11="",H11="",I11=""),"",IF(H11="",N(G11),N(H11))-N(I11)) | O11: Pastel | P11: =SUMIF($A$8:$A$53,O11,$G$8:$G$53) | Q11: =IF(OR(PresupuestoTotal="",PresupuestoTotal=0),"",P11/PresupuestoTotal) | R11: =SUMIF($A$8:$A$53,O11,$I$8:$I$53)
A12: Banquete | B12: Cóctel o mesa de bocadillos | C12: No | E12: =IF(D12<>"",D12,IF(C12="Sí",IF(InvitadosPrevistos="", "",InvitadosPrevistos),"")) | G12: =IF(OR(E12="",F12=""),"",E12*F12) | J12: =IF(AND(G12="",H12="",I12=""),"",IF(H12="",N(G12),N(H12))-N(I12)) | O12: Música | P12: =SUMIF($A$8:$A$53,O12,$G$8:$G$53) | Q12: =IF(OR(PresupuestoTotal="",PresupuestoTotal=0),"",P12/PresupuestoTotal) | R12: =SUMIF($A$8:$A$53,O12,$I$8:$I$53)
A13: Banquete | B13: Personal de servicio | C13: No | E13: =IF(D13<>"",D13,IF(C13="Sí",IF(InvitadosPrevistos="", "",InvitadosPrevistos),"")) | G13: =IF(OR(E13="",F13=""),"",E13*F13) | J13: =IF(AND(G13="",H13="",I13=""),"",IF(H13="",N(G13),N(H13))-N(I13)) | O13: Foto y video | P13: =SUMIF($A$8:$A$53,O13,$G$8:$G$53) | Q13: =IF(OR(PresupuestoTotal="",PresupuestoTotal=0),"",P13/PresupuestoTotal) | R13: =SUMIF($A$8:$A$53,O13,$I$8:$I$53)
A14: Bebidas | B14: Barra por persona | C14: Sí | E14: =IF(D14<>"",D14,IF(C14="Sí",IF(InvitadosPrevistos="", "",InvitadosPrevistos),"")) | G14: =IF(OR(E14="",F14=""),"",E14*F14) | J14: =IF(AND(G14="",H14="",I14=""),"",IF(H14="",N(G14),N(H14))-N(I14)) | O14: Flores y decoración | P14: =SUMIF($A$8:$A$53,O14,$G$8:$G$53) | Q14: =IF(OR(PresupuestoTotal="",PresupuestoTotal=0),"",P14/PresupuestoTotal) | R14: =SUMIF($A$8:$A$53,O14,$I$8:$I$53)
A15: Bebidas | B15: Brindis por persona | C15: Sí | E15: =IF(D15<>"",D15,IF(C15="Sí",IF(InvitadosPrevistos="", "",InvitadosPrevistos),"")) | G15: =IF(OR(E15="",F15=""),"",E15*F15) | J15: =IF(AND(G15="",H15="",I15=""),"",IF(H15="",N(G15),N(H15))-N(I15)) | O15: Invitaciones | P15: =SUMIF($A$8:$A$53,O15,$G$8:$G$53) | Q15: =IF(OR(PresupuestoTotal="",PresupuestoTotal=0),"",P15/PresupuestoTotal) | R15: =SUMIF($A$8:$A$53,O15,$I$8:$I$53)
A16: Bebidas | B16: Hielo, cristalería y barra | C16: No | E16: =IF(D16<>"",D16,IF(C16="Sí",IF(InvitadosPrevistos="", "",InvitadosPrevistos),"")) | G16: =IF(OR(E16="",F16=""),"",E16*F16) | J16: =IF(AND(G16="",H16="",I16=""),"",IF(H16="",N(G16),N(H16))-N(I16)) | O16: Vestuario | P16: =SUMIF($A$8:$A$53,O16,$G$8:$G$53) | Q16: =IF(OR(PresupuestoTotal="",PresupuestoTotal=0),"",P16/PresupuestoTotal) | R16: =SUMIF($A$8:$A$53,O16,$I$8:$I$53)
A17: Pastel | B17: Pastel | C17: No | E17: =IF(D17<>"",D17,IF(C17="Sí",IF(InvitadosPrevistos="", "",InvitadosPrevistos),"")) | G17: =IF(OR(E17="",F17=""),"",E17*F17) | J17: =IF(AND(G17="",H17="",I17=""),"",IF(H17="",N(G17),N(H17))-N(I17)) | O17: Belleza | P17: =SUMIF($A$8:$A$53,O17,$G$8:$G$53) | Q17: =IF(OR(PresupuestoTotal="",PresupuestoTotal=0),"",P17/PresupuestoTotal) | R17: =SUMIF($A$8:$A$53,O17,$I$8:$I$53)
A18: Pastel | B18: Mesa de postres | C18: No | E18: =IF(D18<>"",D18,IF(C18="Sí",IF(InvitadosPrevistos="", "",InvitadosPrevistos),"")) | G18: =IF(OR(E18="",F18=""),"",E18*F18) | J18: =IF(AND(G18="",H18="",I18=""),"",IF(H18="",N(G18),N(H18))-N(I18)) | O18: Transporte | P18: =SUMIF($A$8:$A$53,O18,$G$8:$G$53) | Q18: =IF(OR(PresupuestoTotal="",PresupuestoTotal=0),"",P18/PresupuestoTotal) | R18: =SUMIF($A$8:$A$53,O18,$I$8:$I$53)
A19: Música | B19: DJ, grupo o banda | C19: No | E19: =IF(D19<>"",D19,IF(C19="Sí",IF(InvitadosPrevistos="", "",InvitadosPrevistos),"")) | G19: =IF(OR(E19="",F19=""),"",E19*F19) | J19: =IF(AND(G19="",H19="",I19=""),"",IF(H19="",N(G19),N(H19))-N(I19)) | O19: Mobiliario | P19: =SUMIF($A$8:$A$53,O19,$G$8:$G$53) | Q19: =IF(OR(PresupuestoTotal="",PresupuestoTotal=0),"",P19/PresupuestoTotal) | R19: =SUMIF($A$8:$A$53,O19,$I$8:$I$53)
... A22: Foto y video | B22: Fotografía | C22: No | E22: =IF(D22<>"",D22,IF(C22="Sí",IF(InvitadosPrevistos="", "",InvitadosPrevistos),"")) | G22: =IF(OR(E22="",F22=""),"",E22*F22) | J22: =IF(AND(G22="",H22="",I22=""),"",IF(H22="",N(G22),N(H22))-N(I22)) | O22: Otra | P22: =SUMIF($A$8:$A$53,O22,$G$8:$G$53) | Q22: =IF(OR(PresupuestoTotal="",PresupuestoTotal=0),"",P22/PresupuestoTotal) | R22: =SUMIF($A$8:$A$53,O22,$I$8:$I$53)
A23: Foto y video | B23: Video | C23: No | E23: =IF(D23<>"",D23,IF(C23="Sí",IF(InvitadosPrevistos="", "",InvitadosPrevistos),"")) | G23: =IF(OR(E23="",F23=""),"",E23*F23) | J23: =IF(AND(G23="",H23="",I23=""),"",IF(H23="",N(G23),N(H23))-N(I23)) | O23: Sin categoría | P23: =SUM($G$8:$G$53)-SUM($P$8:$P$22) | Q23: =IF(OR(PresupuestoTotal="",PresupuestoTotal=0),"",P23/PresupuestoTotal) | R23: =SUM($I$8:$I$53)-SUM($R$8:$R$22)
A24: Foto y video | B24: Álbum o entrega digital | C24: No | E24: =IF(D24<>"",D24,IF(C24="Sí",IF(InvitadosPrevistos="", "",InvitadosPrevistos),"")) | G24: =IF(OR(E24="",F24=""),"",E24*F24) | J24: =IF(AND(G24="",H24="",I24=""),"",IF(H24="",N(G24),N(H24))-N(I24)) | O24: Reserva | P24: =Inicio!H7 | Q24: =IF(OR(PresupuestoTotal="",PresupuestoTotal=0),"",P24/PresupuestoTotal) | R24: 0
A25: Flores y decoración | B25: Decoración de la ceremonia | C25: No | E25: =IF(D25<>"",D25,IF(C25="Sí",IF(InvitadosPrevistos="", "",InvitadosPrevistos),"")) | G25: =IF(OR(E25="",F25=""),"",E25*F25) | J25: =IF(AND(G25="",H25="",I25=""),"",IF(H25="",N(G25),N(H25))-N(I25))
A26: Flores y decoración | B26: Centros de mesa | C26: No | E26: =IF(D26<>"",D26,IF(C26="Sí",IF(InvitadosPrevistos="", "",InvitadosPrevistos),"")) | G26: =IF(OR(E26="",F26=""),"",E26*F26) | J26: =IF(AND(G26="",H26="",I26=""),"",IF(H26="",N(G26),N(H26))-N(I26))
A27: Flores y decoración | B27: Iluminación decorativa | C27: No | E27: =IF(D27<>"",D27,IF(C27="Sí",IF(InvitadosPrevistos="", "",InvitadosPrevistos),"")) | G27: =IF(OR(E27="",F27=""),"",E27*F27) | J27: =IF(AND(G27="",H27="",I27=""),"",IF(H27="",N(G27),N(H27))-N(I27))
A28: Invitaciones | B28: Save the date | C28: No | E28: =IF(D28<>"",D28,IF(C28="Sí",IF(InvitadosPrevistos="", "",InvitadosPrevistos),"")) | G28: =IF(OR(E28="",F28=""),"",E28*F28) | J28: =IF(AND(G28="",H28="",I28=""),"",IF(H28="",N(G28),N(H28))-N(I28))
A29: Invitaciones | B29: Invitaciones | C29: No | E29: =IF(D29<>"",D29,IF(C29="Sí",IF(InvitadosPrevistos="", "",InvitadosPrevistos),"")) | G29: =IF(OR(E29="",F29=""),"",E29*F29) | J29: =IF(AND(G29="",H29="",I29=""),"",IF(H29="",N(G29),N(H29))-N(I29))
A30: Invitaciones | B30: Señalética y menús impresos | C30: No | E30: =IF(D30<>"",D30,IF(C30="Sí",IF(InvitadosPrevistos="", "",InvitadosPrevistos),"")) | G30: =IF(OR(E30="",F30=""),"",E30*F30) | J30: =IF(AND(G30="",H30="",I30=""),"",IF(H30="",N(G30),N(H30))-N(I30))
A31: Vestuario | B31: Vestido o traje | C31: No | E31: =IF(D31<>"",D31,IF(C31="Sí",IF(InvitadosPrevistos="", "",InvitadosPrevistos),"")) | G31: =IF(OR(E31="",F31=""),"",E31*F31) | J31: =IF(AND(G31="",H31="",I31=""),"",IF(H31="",N(G31),N(H31))-N(I31))
A32: Vestuario | B32: Accesorios | C32: No | E32: =IF(D32<>"",D32,IF(C32="Sí",IF(InvitadosPrevistos="", "",InvitadosPrevistos),"")) | G32: =IF(OR(E32="",F32=""),"",E32*F32) | J32: =IF(AND(G32="",H32="",I32=""),"",IF(H32="",N(G32),N(H32))-N(I32))
A33: Belleza | B33: Maquillaje y peinado | C33: No | E33: =IF(D33<>"",D33,IF(C33="Sí",IF(InvitadosPrevistos="", "",InvitadosPrevistos),"")) | G33: =IF(OR(E33="",F33=""),"",E33*F33) | J33: =IF(AND(G33="",H33="",I33=""),"",IF(H33="",N(G33),N(H33))-N(I33))
A34: Belleza | B34: Prueba de belleza | C34: No | E34: =IF(D34<>"",D34,IF(C34="Sí",IF(InvitadosPrevistos="", "",InvitadosPrevistos),"")) | G34: =IF(OR(E34="",F34=""),"",E34*F34) | J34: =IF(AND(G34="",H34="",I34=""),"",IF(H34="",N(G34),N(H34))-N(I34))
A35: Transporte | B35: Traslado de la pareja | C35: No | E35: =IF(D35<>"",D35,IF(C35="Sí",IF(InvitadosPrevistos="", "",InvitadosPrevistos),"")) | G35: =IF(OR(E35="",F35=""),"",E35*F35) | J35: =IF(AND(G35="",H35="",I35=""),"",IF(H35="",N(G35),N(H35))-N(I35))
A36: Transporte | B36: Traslado de invitados | C36: No | E36: =IF(D36<>"",D36,IF(C36="Sí",IF(InvitadosPrevistos="", "",InvitadosPrevistos),"")) | G36: =IF(OR(E36="",F36=""),"",E36*F36) | J36: =IF(AND(G36="",H36="",I36=""),"",IF(H36="",N(G36),N(H36))-N(I36))
... A41: Coordinación | B41: Maestro de ceremonias | C41: No | E41: =IF(D41<>"",D41,IF(C41="Sí",IF(InvitadosPrevistos="", "",InvitadosPrevistos),"")) | G41: =IF(OR(E41="",F41=""),"",E41*F41) | J41: =IF(AND(G41="",H41="",I41=""),"",IF(H41="",N(G41),N(H41))-N(I41))
E42: =IF(D42<>"",D42,IF(C42="Sí",IF(InvitadosPrevistos="", "",InvitadosPrevistos),"")) | G42: =IF(OR(E42="",F42=""),"",E42*F42) | J42: =IF(AND(G42="",H42="",I42=""),"",IF(H42="",N(G42),N(H42))-N(I42))
E43: =IF(D43<>"",D43,IF(C43="Sí",IF(InvitadosPrevistos="", "",InvitadosPrevistos),"")) | G43: =IF(OR(E43="",F43=""),"",E43*F43) | J43: =IF(AND(G43="",H43="",I43=""),"",IF(H43="",N(G43),N(H43))-N(I43))
E44: =IF(D44<>"",D44,IF(C44="Sí",IF(InvitadosPrevistos="", "",InvitadosPrevistos),"")) | G44: =IF(OR(E44="",F44=""),"",E44*F44) | J44: =IF(AND(G44="",H44="",I44=""),"",IF(H44="",N(G44),N(H44))-N(I44))
E45: =IF(D45<>"",D45,IF(C45="Sí",IF(InvitadosPrevistos="", "",InvitadosPrevistos),"")) | G45: =IF(OR(E45="",F45=""),"",E45*F45) | J45: =IF(AND(G45="",H45="",I45=""),"",IF(H45="",N(G45),N(H45))-N(I45))
E46: =IF(D46<>"",D46,IF(C46="Sí",IF(InvitadosPrevistos="", "",InvitadosPrevistos),"")) | G46: =IF(OR(E46="",F46=""),"",E46*F46) | J46: =IF(AND(G46="",H46="",I46=""),"",IF(H46="",N(G46),N(H46))-N(I46))
E47: =IF(D47<>"",D47,IF(C47="Sí",IF(InvitadosPrevistos="", "",InvitadosPrevistos),"")) | G47: =IF(OR(E47="",F47=""),"",E47*F47) | J47: =IF(AND(G47="",H47="",I47=""),"",IF(H47="",N(G47),N(H47))-N(I47))
...

Sheet Invitados
A1: Invitados
A2: Borra las filas que empiezan con EJEMPLO. Una fila puede ser una persona o una familia: anota adultos y niños. Si en la misma fila hay menús distintos, sepárala.
A7: Nombre | B7: Grupo o familia | C7: Lado | D7: Relación | E7: Teléfono | F7: Correo | G7: Adultos | H7: Niños | I7: Total | J7: Invitación | K7: RSVP | L7: Asisten | M7: Menú | N7: Mesa | O7: Notas
A8: EJEMPLO · Ana López | B8: Familia López | C8: Novia | D8: Hermana | G8: 2 | H8: 0 | I8: =IF(AND(G8="",H8=""),"",N(G8)+N(H8)) | J8: Enviada | K8: Confirmado | L8: =IF(OR(K8="",K8="Pendiente"),"",IF(K8="Rechazado",0,IF(K8="Confirmado",IF(I8="","",I8),""))) | M8: Estándar | N8: 1
A9: EJEMPLO · Luis Pérez | B9: Familia López | C9: Novio | D9: Amigo | G9: 1 | H9: 0 | I9: =IF(AND(G9="",H9=""),"",N(G9)+N(H9)) | J9: Enviada | K9: Pendiente | L9: =IF(OR(K9="",K9="Pendiente"),"",IF(K9="Rechazado",0,IF(K9="Confirmado",IF(I9="","",I9),""))) | M9: Estándar | N9: 1
A10: EJEMPLO · Maya Ruiz | B10: Familia Ruiz | C10: Novia | D10: Prima | G10: 2 | H10: 1 | I10: =IF(AND(G10="",H10=""),"",N(G10)+N(H10)) | J10: Entregada | K10: Confirmado | L10: =IF(OR(K10="",K10="Pendiente"),"",IF(K10="Rechazado",0,IF(K10="Confirmado",IF(I10="","",I10),""))) | M10: Vegetariano | N10: 2
A11: EJEMPLO · Jorge Díaz | B11: Trabajo | C11: Novio | D11: Compañero de trabajo | G11: 1 | H11: 0 | I11: =IF(AND(G11="",H11=""),"",N(G11)+N(H11)) | J11: Enviada | K11: Rechazado | L11: =IF(OR(K11="",K11="Pendiente"),"",IF(K11="Rechazado",0,IF(K11="Confirmado",IF(I11="","",I11),""))) | M11: Estándar
I12: =IF(AND(G12="",H12=""),"",N(G12)+N(H12)) | L12: =IF(OR(K12="",K12="Pendiente"),"",IF(K12="Rechazado",0,IF(K12="Confirmado",IF(I12="","",I12),"")))
I13: =IF(AND(G13="",H13=""),"",N(G13)+N(H13)) | L13: =IF(OR(K13="",K13="Pendiente"),"",IF(K13="Rechazado",0,IF(K13="Confirmado",IF(I13="","",I13),"")))
I14: =IF(AND(G14="",H14=""),"",N(G14)+N(H14)) | L14: =IF(OR(K14="",K14="Pendiente"),"",IF(K14="Rechazado",0,IF(K14="Confirmado",IF(I14="","",I14),"")))
I15: =IF(AND(G15="",H15=""),"",N(G15)+N(H15)) | L15: =IF(OR(K15="",K15="Pendiente"),"",IF(K15="Rechazado",0,IF(K15="Confirmado",IF(I15="","",I15),"")))
I16: =IF(AND(G16="",H16=""),"",N(G16)+N(H16)) | L16: =IF(OR(K16="",K16="Pendiente"),"",IF(K16="Rechazado",0,IF(K16="Confirmado",IF(I16="","",I16),"")))
I17: =IF(AND(G17="",H17=""),"",N(G17)+N(H17)) | L17: =IF(OR(K17="",K17="Pendiente"),"",IF(K17="Rechazado",0,IF(K17="Confirmado",IF(I17="","",I17),"")))
I18: =IF(AND(G18="",H18=""),"",N(G18)+N(H18)) | L18: =IF(OR(K18="",K18="Pendiente"),"",IF(K18="Rechazado",0,IF(K18="Confirmado",IF(I18="","",I18),"")))
I19: =IF(AND(G19="",H19=""),"",N(G19)+N(H19)) | L19: =IF(OR(K19="",K19="Pendiente"),"",IF(K19="Rechazado",0,IF(K19="Confirmado",IF(I19="","",I19),"")))
I20: =IF(AND(G20="",H20=""),"",N(G20)+N(H20)) | L20: =IF(OR(K20="",K20="Pendiente"),"",IF(K20="Rechazado",0,IF(K20="Confirmado",IF(I20="","",I20),"")))
I21: =IF(AND(G21="",H21=""),"",N(G21)+N(H21)) | L21: =IF(OR(K21="",K21="Pendiente"),"",IF(K21="Rechazado",0,IF(K21="Confirmado",IF(I21="","",I21),"")))
I22: =IF(AND(G22="",H22=""),"",N(G22)+N(H22)) | L22: =IF(OR(K22="",K22="Pendiente"),"",IF(K22="Rechazado",0,IF(K22="Confirmado",IF(I22="","",I22),"")))
I23: =IF(AND(G23="",H23=""),"",N(G23)+N(H23)) | L23: =IF(OR(K23="",K23="Pendiente"),"",IF(K23="Rechazado",0,IF(K23="Confirmado",IF(I23="","",I23),"")))
... I107: =IF(AND(G107="",H107=""),"",N(G107)+N(H107)) | L107: =IF(OR(K107="",K107="Pendiente"),"",IF(K107="Rechazado",0,IF(K107="Confirmado",IF(I107="","",I107),"")))

Sheet Mesas
A1: Mesas
A2: Escribe la capacidad solo de las mesas que vas a usar. Asigna ese mismo número en Invitados. Apartados no cuenta a quien rechazó. Las mesas 1 y 2 traen una capacidad de ejemplo.
A4: Lugares | B4: =SUM(C8:C27) | C4: Apartados | D4: =SUM(D8:D27) | E4: Confirmados | F4: =SUM(E8:E27)
A5: Mesas en uso | B5: =COUNTIF(C8:C27,">0") | C5: Libres | D5: =SUM(F8:F27)
A7: Mesa | B7: Nombre | C7: Capacidad | D7: Apartados | E7: Confirmados | F7: Libres | G7: Notas
A8: 1 | C8: 8 | D8: =SUMIF(Invitados!$N$8:$N$107,A8,Invitados!$I$8:$I$107)-SUMIFS(Invitados!$I$8:$I$107,Invitados!$N$8:$N$107,A8,Invitados!$K$8:$K$107,"Rechazado") | E8: =SUMIFS(Invitados!$I$8:$I$107,Invitados!$N$8:$N$107,A8,Invitados!$K$8:$K$107,"Confirmado") | F8: =IF(C8="","",C8-D8) | G8: Capacidad de ejemplo. Cámbiala o bórrala.
A9: 2 | C9: 8 | D9: =SUMIF(Invitados!$N$8:$N$107,A9,Invitados!$I$8:$I$107)-SUMIFS(Invitados!$I$8:$I$107,Invitados!$N$8:$N$107,A9,Invitados!$K$8:$K$107,"Rechazado") | E9: =SUMIFS(Invitados!$I$8:$I$107,Invitados!$N$8:$N$107,A9,Invitados!$K$8:$K$107,"Confirmado") | F9: =IF(C9="","",C9-D9) | G9: Capacidad de ejemplo. Cámbiala o bórrala.
A10: 3 | D10: =SUMIF(Invitados!$N$8:$N$107,A10,Invitados!$I$8:$I$107)-SUMIFS(Invitados!$I$8:$I$107,Invitados!$N$8:$N$107,A10,Invitados!$K$8:$K$107,"Rechazado") | E10: =SUMIFS(Invitados!$I$8:$I$107,Invitados!$N$8:$N$107,A10,Invitados!$K$8:$K$107,"Confirmado") | F10: =IF(C10="","",C10-D10)
A11: 4 | D11: =SUMIF(Invitados!$N$8:$N$107,A11,Invitados!$I$8:$I$107)-SUMIFS(Invitados!$I$8:$I$107,Invitados!$N$8:$N$107,A11,Invitados!$K$8:$K$107,"Rechazado") | E11: =SUMIFS(Invitados!$I$8:$I$107,Invitados!$N$8:$N$107,A11,Invitados!$K$8:$K$107,"Confirmado") | F11: =IF(C11="","",C11-D11)
A12: 5 | D12: =SUMIF(Invitados!$N$8:$N$107,A12,Invitados!$I$8:$I$107)-SUMIFS(Invitados!$I$8:$I$107,Invitados!$N$8:$N$107,A12,Invitados!$K$8:$K$107,"Rechazado") | E12: =SUMIFS(Invitados!$I$8:$I$107,Invitados!$N$8:$N$107,A12,Invitados!$K$8:$K$107,"Confirmado") | F12: =IF(C12="","",C12-D12)
A13: 6 | D13: =SUMIF(Invitados!$N$8:$N$107,A13,Invitados!$I$8:$I$107)-SUMIFS(Invitados!$I$8:$I$107,Invitados!$N$8:$N$107,A13,Invitados!$K$8:$K$107,"Rechazado") | E13: =SUMIFS(Invitados!$I$8:$I$107,Invitados!$N$8:$N$107,A13,Invitados!$K$8:$K$107,"Confirmado") | F13: =IF(C13="","",C13-D13)
A14: 7 | D14: =SUMIF(Invitados!$N$8:$N$107,A14,Invitados!$I$8:$I$107)-SUMIFS(Invitados!$I$8:$I$107,Invitados!$N$8:$N$107,A14,Invitados!$K$8:$K$107,"Rechazado") | E14: =SUMIFS(Invitados!$I$8:$I$107,Invitados!$N$8:$N$107,A14,Invitados!$K$8:$K$107,"Confirmado") | F14: =IF(C14="","",C14-D14)
A15: 8 | D15: =SUMIF(Invitados!$N$8:$N$107,A15,Invitados!$I$8:$I$107)-SUMIFS(Invitados!$I$8:$I$107,Invitados!$N$8:$N$107,A15,Invitados!$K$8:$K$107,"Rechazado") | E15: =SUMIFS(Invitados!$I$8:$I$107,Invitados!$N$8:$N$107,A15,Invitados!$K$8:$K$107,"Confirmado") | F15: =IF(C15="","",C15-D15)
A16: 9 | D16: =SUMIF(Invitados!$N$8:$N$107,A16,Invitados!$I$8:$I$107)-SUMIFS(Invitados!$I$8:$I$107,Invitados!$N$8:$N$107,A16,Invitados!$K$8:$K$107,"Rechazado") | E16: =SUMIFS(Invitados!$I$8:$I$107,Invitados!$N$8:$N$107,A16,Invitados!$K$8:$K$107,"Confirmado") | F16: =IF(C16="","",C16-D16)
A17: 10 | D17: =SUMIF(Invitados!$N$8:$N$107,A17,Invitados!$I$8:$I$107)-SUMIFS(Invitados!$I$8:$I$107,Invitados!$N$8:$N$107,A17,Invitados!$K$8:$K$107,"Rechazado") | E17: =SUMIFS(Invitados!$I$8:$I$107,Invitados!$N$8:$N$107,A17,Invitados!$K$8:$K$107,"Confirmado") | F17: =IF(C17="","",C17-D17)
A18: 11 | D18: =SUMIF(Invitados!$N$8:$N$107,A18,Invitados!$I$8:$I$107)-SUMIFS(Invitados!$I$8:$I$107,Invitados!$N$8:$N$107,A18,Invitados!$K$8:$K$107,"Rechazado") | E18: =SUMIFS(Invitados!$I$8:$I$107,Invitados!$N$8:$N$107,A18,Invitados!$K$8:$K$107,"Confirmado") | F18: =IF(C18="","",C18-D18)
A19: 12 | D19: =SUMIF(Invitados!$N$8:$N$107,A19,Invitados!$I$8:$I$107)-SUMIFS(Invitados!$I$8:$I$107,Invitados!$N$8:$N$107,A19,Invitados!$K$8:$K$107,"Rechazado") | E19: =SUMIFS(Invitados!$I$8:$I$107,Invitados!$N$8:$N$107,A19,Invitados!$K$8:$K$107,"Confirmado") | F19: =IF(C19="","",C19-D19)
A20: 13 | D20: =SUMIF(Invitados!$N$8:$N$107,A20,Invitados!$I$8:$I$107)-SUMIFS(Invitados!$I$8:$I$107,Invitados!$N$8:$N$107,A20,Invitados!$K$8:$K$107,"Rechazado") | E20: =SUMIFS(Invitados!$I$8:$I$107,Invitados!$N$8:$N$107,A20,Invitados!$K$8:$K$107,"Confirmado") | F20: =IF(C20="","",C20-D20)
A21: 14 | D21: =SUMIF(Invitados!$N$8:$N$107,A21,Invitados!$I$8:$I$107)-SUMIFS(Invitados!$I$8:$I$107,Invitados!$N$8:$N$107,A21,Invitados!$K$8:$K$107,"Rechazado") | E21: =SUMIFS(Invitados!$I$8:$I$107,Invitados!$N$8:$N$107,A21,Invitados!$K$8:$K$107,"Confirmado") | F21: =IF(C21="","",C21-D21)
... A27: 20 | D27: =SUMIF(Invitados!$N$8:$N$107,A27,Invitados!$I$8:$I$107)-SUMIFS(Invitados!$I$8:$I$107,Invitados!$N$8:$N$107,A27,Invitados!$K$8:$K$107,"Rechazado") | E27: =SUMIFS(Invitados!$I$8:$I$107,Invitados!$N$8:$N$107,A27,Invitados!$K$8:$K$107,"Confirmado") | F27: =IF(C27="","",C27-D27)

Sheet Menú
A1: Menú
A2: Las porciones usan a las personas confirmadas. Si todavía no hay confirmados, usan los invitados previstos. El dinero de la comida se anota en Presupuesto, no aquí.
A7: Momento | B7: Qué se sirve | C7: Descripción | D7: Ajuste | E7: Porciones | F7: Notas | H7: Menú | I7: Confirmadas | J7: En la lista
A8: Cóctel | B8: Bocadillos salados | C8: Algo para picar al llegar | E8: =IF(AND(A8="",B8=""),"",IF(D8<>"",D8,IF(PersonasConfirmadas>0,PersonasConfirmadas,IF(InvitadosPrevistos="","",InvitadosPrevistos)))) | H8: Estándar | I8: =SUMIFS(Invitados!$I$8:$I$107,Invitados!$M$8:$M$107,H8,Invitados!$K$8:$K$107,"Confirmado") | J8: =SUMIF(Invitados!$M$8:$M$107,H8,Invitados!$I$8:$I$107)
A9: Cóctel | B9: Estación para picar | C9: Quesos, fruta o lo que prefieran | E9: =IF(AND(A9="",B9=""),"",IF(D9<>"",D9,IF(PersonasConfirmadas>0,PersonasConfirmadas,IF(InvitadosPrevistos="","",InvitadosPrevistos)))) | H9: Vegetariano | I9: =SUMIFS(Invitados!$I$8:$I$107,Invitados!$M$8:$M$107,H9,Invitados!$K$8:$K$107,"Confirmado") | J9: =SUMIF(Invitados!$M$8:$M$107,H9,Invitados!$I$8:$I$107)
A10: Cena | B10: Entrada | E10: =IF(AND(A10="",B10=""),"",IF(D10<>"",D10,IF(PersonasConfirmadas>0,PersonasConfirmadas,IF(InvitadosPrevistos="","",InvitadosPrevistos)))) | H10: Vegano | I10: =SUMIFS(Invitados!$I$8:$I$107,Invitados!$M$8:$M$107,H10,Invitados!$K$8:$K$107,"Confirmado") | J10: =SUMIF(Invitados!$M$8:$M$107,H10,Invitados!$I$8:$I$107)
A11: Cena | B11: Plato fuerte | E11: =IF(AND(A11="",B11=""),"",IF(D11<>"",D11,IF(PersonasConfirmadas>0,PersonasConfirmadas,IF(InvitadosPrevistos="","",InvitadosPrevistos)))) | H11: Sin gluten | I11: =SUMIFS(Invitados!$I$8:$I$107,Invitados!$M$8:$M$107,H11,Invitados!$K$8:$K$107,"Confirmado") | J11: =SUMIF(Invitados!$M$8:$M$107,H11,Invitados!$I$8:$I$107)
A12: Cena | B12: Opción vegetariana | C12: Cuadra este plato con el conteo de la derecha | E12: =IF(AND(A12="",B12=""),"",IF(D12<>"",D12,IF(PersonasConfirmadas>0,PersonasConfirmadas,IF(InvitadosPrevistos="","",InvitadosPrevistos)))) | H12: Infantil | I12: =SUMIFS(Invitados!$I$8:$I$107,Invitados!$M$8:$M$107,H12,Invitados!$K$8:$K$107,"Confirmado") | J12: =SUMIF(Invitados!$M$8:$M$107,H12,Invitados!$I$8:$I$107)
A13: Cena | B13: Plato para niños | E13: =IF(AND(A13="",B13=""),"",IF(D13<>"",D13,IF(PersonasConfirmadas>0,PersonasConfirmadas,IF(InvitadosPrevistos="","",InvitadosPrevistos)))) | H13: Otro | I13: =SUMIFS(Invitados!$I$8:$I$107,Invitados!$M$8:$M$107,H13,Invitados!$K$8:$K$107,"Confirmado") | J13: =SUMIF(Invitados!$M$8:$M$107,H13,Invitados!$I$8:$I$107)
A14: Postre | B14: Pastel | C14: Piensa en una rebanada por persona | E14: =IF(AND(A14="",B14=""),"",IF(D14<>"",D14,IF(PersonasConfirmadas>0,PersonasConfirmadas,IF(InvitadosPrevistos="","",InvitadosPrevistos)))) | H14: Sin menú elegido | I14: =SUMIFS(Invitados!$I$8:$I$107,Invitados!$M$8:$M$107,"",Invitados!$K$8:$K$107,"Confirmado") | J14: =SUMIF(Invitados!$M$8:$M$107,"",Invitados!$I$8:$I$107)
A15: Postre | B15: Mesa de postres | C15: Opcional | E15: =IF(AND(A15="",B15=""),"",IF(D15<>"",D15,IF(PersonasConfirmadas>0,PersonasConfirmadas,IF(InvitadosPrevistos="","",InvitadosPrevistos))))
A16: Barra | B16: Trago de bienvenida | E16: =IF(AND(A16="",B16=""),"",IF(D16<>"",D16,IF(PersonasConfirmadas>0,PersonasConfirmadas,IF(InvitadosPrevistos="","",InvitadosPrevistos))))
A17: Barra | B17: Bebidas de la cena | E17: =IF(AND(A17="",B17=""),"",IF(D17<>"",D17,IF(PersonasConfirmadas>0,PersonasConfirmadas,IF(InvitadosPrevistos="","",InvitadosPrevistos))))
A18: Barra | B18: Brindis | E18: =IF(AND(A18="",B18=""),"",IF(D18<>"",D18,IF(PersonasConfirmadas>0,PersonasConfirmadas,IF(InvitadosPrevistos="","",InvitadosPrevistos))))
A19: Barra | B19: Después de la cena | E19: =IF(AND(A19="",B19=""),"",IF(D19<>"",D19,IF(PersonasConfirmadas>0,PersonasConfirmadas,IF(InvitadosPrevistos="","",InvitadosPrevistos))))
E20: =IF(AND(A20="",B20=""),"",IF(D20<>"",D20,IF(PersonasConfirmadas>0,PersonasConfirmadas,IF(InvitadosPrevistos="","",InvitadosPrevistos))))
E21: =IF(AND(A21="",B21=""),"",IF(D21<>"",D21,IF(PersonasConfirmadas>0,PersonasConfirmadas,IF(InvitadosPrevistos="","",InvitadosPrevistos))))
E22: =IF(AND(A22="",B22=""),"",IF(D22<>"",D22,IF(PersonasConfirmadas>0,PersonasConfirmadas,IF(InvitadosPrevistos="","",InvitadosPrevistos))))
E23: =IF(AND(A23="",B23=""),"",IF(D23<>"",D23,IF(PersonasConfirmadas>0,PersonasConfirmadas,IF(InvitadosPrevistos="","",InvitadosPrevistos))))
E24: =IF(AND(A24="",B24=""),"",IF(D24<>"",D24,IF(PersonasConfirmadas>0,PersonasConfirmadas,IF(InvitadosPrevistos="","",InvitadosPrevistos))))
E25: =IF(AND(A25="",B25=""),"",IF(D25<>"",D25,IF(PersonasConfirmadas>0,PersonasConfirmadas,IF(InvitadosPrevistos="","",InvitadosPrevistos))))
E26: =IF(AND(A26="",B26=""),"",IF(D26<>"",D26,IF(PersonasConfirmadas>0,PersonasConfirmadas,IF(InvitadosPrevistos="","",InvitadosPrevistos))))
E27: =IF(AND(A27="",B27=""),"",IF(D27<>"",D27,IF(PersonasConfirmadas>0,PersonasConfirmadas,IF(InvitadosPrevistos="","",InvitadosPrevistos))))

Sheet Proveedores
A1: Proveedores
A2: Aquí van contactos y cotizaciones, también las que no vas a contratar. Si escribes Pagado, el saldo usa ese total. Si Pagado está vacío, resta solo el anticipo. El monto elegido se copia a Presupuesto.
A7: Categoría | B7: Proveedor | C7: Contacto | D7: Teléfono | E7: Correo | F7: Qué incluye | G7: Cotización | H7: Anticipo | I7: Pagado | J7: Saldo | K7: Fecha límite | L7: Estado | M7: Notas
A8: Lugar | J8: =IF(AND(G8="",H8="",I8=""),"",N(G8)-IF(I8="",N(H8),N(I8)))
A9: Banquete | J9: =IF(AND(G9="",H9="",I9=""),"",N(G9)-IF(I9="",N(H9),N(I9)))
A10: Bebidas | J10: =IF(AND(G10="",H10="",I10=""),"",N(G10)-IF(I10="",N(H10),N(I10)))
A11: Pastel | J11: =IF(AND(G11="",H11="",I11=""),"",N(G11)-IF(I11="",N(H11),N(I11)))
A12: Música | J12: =IF(AND(G12="",H12="",I12=""),"",N(G12)-IF(I12="",N(H12),N(I12)))
A13: Foto y video | J13: =IF(AND(G13="",H13="",I13=""),"",N(G13)-IF(I13="",N(H13),N(I13)))
A14: Flores y decoración | J14: =IF(AND(G14="",H14="",I14=""),"",N(G14)-IF(I14="",N(H14),N(I14)))
A15: Invitaciones | J15: =IF(AND(G15="",H15="",I15=""),"",N(G15)-IF(I15="",N(H15),N(I15)))
A16: Vestuario | J16: =IF(AND(G16="",H16="",I16=""),"",N(G16)-IF(I16="",N(H16),N(I16)))
A17: Belleza | J17: =IF(AND(G17="",H17="",I17=""),"",N(G17)-IF(I17="",N(H17),N(I17)))
A18: Transporte | J18: =IF(AND(G18="",H18="",I18=""),"",N(G18)-IF(I18="",N(H18),N(I18)))
A19: Mobiliario | J19: =IF(AND(G19="",H19="",I19=""),"",N(G19)-IF(I19="",N(H19),N(I19)))
... A22: Otra | J22: =IF(AND(G22="",H22="",I22=""),"",N(G22)-IF(I22="",N(H22),N(I22)))
J23: =IF(AND(G23="",H23="",I23=""),"",N(G23)-IF(I23="",N(H23),N(I23)))
J24: =IF(AND(G24="",H24="",I24=""),"",N(G24)-IF(I24="",N(H24),N(I24)))
J25: =IF(AND(G25="",H25="",I25=""),"",N(G25)-IF(I25="",N(H25),N(I25)))
J26: =IF(AND(G26="",H26="",I26=""),"",N(G26)-IF(I26="",N(H26),N(I26)))
J27: =IF(AND(G27="",H27="",I27=""),"",N(G27)-IF(I27="",N(H27),N(I27)))
J28: =IF(AND(G28="",H28="",I28=""),"",N(G28)-IF(I28="",N(H28),N(I28)))
J29: =IF(AND(G29="",H29="",I29=""),"",N(G29)-IF(I29="",N(H29),N(I29)))
J30: =IF(AND(G30="",H30="",I30=""),"",N(G30)-IF(I30="",N(H30),N(I30)))
J31: =IF(AND(G31="",H31="",I31=""),"",N(G31)-IF(I31="",N(H31),N(I31)))
J32: =IF(AND(G32="",H32="",I32=""),"",N(G32)-IF(I32="",N(H32),N(I32)))
J33: =IF(AND(G33="",H33="",I33=""),"",N(G33)-IF(I33="",N(H33),N(I33)))
J34: =IF(AND(G34="",H34="",I34=""),"",N(G34)-IF(I34="",N(H34),N(I34)))

Sheet Tareas
A1: Tareas
A2: La fecha límite resta los días a la fecha de la fiesta. Cambia Días antes si quieres mover una tarea. Inicio cuenta como avance las que marcas Hecho.
A7: Fase | B7: Tarea | C7: Responsable | D7: Días antes | E7: Fecha límite | F7: Prioridad | G7: Estado | H7: Notas
A8: Con 12 meses | B8: Definir la fecha y la ciudad | D8: 365 | E8: =IF(OR(FechaFiesta="",D8=""),"",FechaFiesta-D8) | F8: Alta | G8: Por hacer
A9: Con 12 meses | B9: Acordar el presupuesto total | D9: 360 | E9: =IF(OR(FechaFiesta="",D9=""),"",FechaFiesta-D9) | F9: Alta | G9: Por hacer
A10: Con 12 meses | B10: Hacer la lista preliminar de invitados | D10: 340 | E10: =IF(OR(FechaFiesta="",D10=""),"",FechaFiesta-D10) | F10: Alta | G10: Por hacer
A11: Con 12 meses | B11: Visitar y apartar el lugar | D11: 300 | E11: =IF(OR(FechaFiesta="",D11=""),"",FechaFiesta-D11) | F11: Alta | G11: Por hacer
A12: De 6 a 9 meses | B12: Definir el estilo de la fiesta | D12: 270 | E12: =IF(OR(FechaFiesta="",D12=""),"",FechaFiesta-D12) | F12: Media | G12: Por hacer
A13: De 6 a 9 meses | B13: Contratar el banquete | D13: 240 | E13: =IF(OR(FechaFiesta="",D13=""),"",FechaFiesta-D13) | F13: Alta | G13: Por hacer
A14: De 6 a 9 meses | B14: Contratar la música | D14: 240 | E14: =IF(OR(FechaFiesta="",D14=""),"",FechaFiesta-D14) | F14: Alta | G14: Por hacer
A15: De 6 a 9 meses | B15: Contratar foto y video | D15: 210 | E15: =IF(OR(FechaFiesta="",D15=""),"",FechaFiesta-D15) | F15: Media | G15: Por hacer
A16: De 6 a 9 meses | B16: Elegir vestuario y agendar pruebas | D16: 210 | E16: =IF(OR(FechaFiesta="",D16=""),"",FechaFiesta-D16) | F16: Media | G16: Por hacer
A17: De 6 a 9 meses | B17: Enviar el save the date | D17: 180 | E17: =IF(OR(FechaFiesta="",D17=""),"",FechaFiesta-D17) | F17: Media | G17: Por hacer
A18: De 3 a 6 meses | B18: Cerrar menú, barra y opción para niños | D18: 150 | E18: =IF(OR(FechaFiesta="",D18=""),"",FechaFiesta-D18) | F18: Alta | G18: Por hacer
A19: De 3 a 6 meses | B19: Encargar el pastel | D19: 140 | E19: =IF(OR(FechaFiesta="",D19=""),"",FechaFiesta-D19) | F19: Media | G19: Por hacer
... A41: El día | B41: Comer algo antes de recibir invitados | D41: 0 | E41: =IF(OR(FechaFiesta="",D41=""),"",FechaFiesta-D41) | F41: Media | G41: Por hacer
E42: =IF(OR(FechaFiesta="",D42=""),"",FechaFiesta-D42)
E43: =IF(OR(FechaFiesta="",D43=""),"",FechaFiesta-D43)
E44: =IF(OR(FechaFiesta="",D44=""),"",FechaFiesta-D44)
E45: =IF(OR(FechaFiesta="",D45=""),"",FechaFiesta-D45)
E46: =IF(OR(FechaFiesta="",D46=""),"",FechaFiesta-D46)
E47: =IF(OR(FechaFiesta="",D47=""),"",FechaFiesta-D47)
E48: =IF(OR(FechaFiesta="",D48=""),"",FechaFiesta-D48)
E49: =IF(OR(FechaFiesta="",D49=""),"",FechaFiesta-D49)

Sheet Horario
A1: Horario de la fiesta
A2: Cambia la hora de inicio y los minutos. Termina se calcula sola. Las horas de inicio no se empujan entre sí: si mueves una, revisa la siguiente. Listo sirve para ir marcando el día.
A7: Empieza | B7: Momento | C7: Minutos | D7: Termina | E7: Quién lo cuida | F7: Lugar | G7: Listo | H7: Notas
A8: 0.625 | B8: Llegan los invitados | C8: 30 | D8: =IF(OR(A8="",C8=""),"",A8+C8/1440)
A9: 0.64583333 | B9: Ceremonia | C9: 40 | D9: =IF(OR(A9="",C9=""),"",A9+C9/1440)
A10: 0.67361111 | B10: Fotos y cóctel | C10: 80 | D10: =IF(OR(A10="",C10=""),"",A10+C10/1440)
A11: 0.72916667 | B11: Entrada a la fiesta | C11: 15 | D11: =IF(OR(A11="",C11=""),"",A11+C11/1440)
A12: 0.73958333 | B12: Brindis | C12: 15 | D12: =IF(OR(A12="",C12=""),"",A12+C12/1440)
A13: 0.75 | B13: Cena | C13: 75 | D13: =IF(OR(A13="",C13=""),"",A13+C13/1440)
A14: 0.80208333 | B14: Pastel y baile de apertura | C14: 25 | D14: =IF(OR(A14="",C14=""),"",A14+C14/1440)
A15: 0.81944444 | B15: Baile | C15: 90 | D15: =IF(OR(A15="",C15=""),"",A15+C15/1440)
A16: 0.88194444 | B16: Hora loca | C16: 50 | D16: =IF(OR(A16="",C16=""),"",A16+C16/1440)
A17: 0.91666667 | B17: Cierre y despedida | C17: 30 | D17: =IF(OR(A17="",C17=""),"",A17+C17/1440)
D18: =IF(OR(A18="",C18=""),"",A18+C18/1440)
D19: =IF(OR(A19="",C19=""),"",A19+C19/1440)
D20: =IF(OR(A20="",C20=""),"",A20+C20/1440)
D21: =IF(OR(A21="",C21=""),"",A21+C21/1440)
D22: =IF(OR(A22="",C22=""),"",A22+C22/1440)
D23: =IF(OR(A23="",C23=""),"",A23+C23/1440)

Sheet Guía
A1: Cómo usar este plan
A2: Ocho hojas para armar la fiesta. Los números se calculan; las celdas claras son las que se llenan.
A4: Empieza en Inicio
A5: Escribe la pareja, la fecha, los invitados que esperas y el presupuesto. La moneda es una etiqueta: los números no se convierten. La reserva aparta un porcentaje del presupuesto, 10% al abrir el archivo. Días restantes usa la fecha de la fiesta.
A7: Presupuesto
A8: Cada fila es un gasto. Si Por persona está en Sí y Ajuste está vacío, la cantidad son los invitados previstos. Estimado es cantidad por costo unitario. Si escribes Contratado, el saldo usa ese monto; si no, usa el estimado. Pagado es lo que ya entregaste. Una fecha de pago en los próximos 14 días se marca en ámbar, y en rojo si ya venció y todavía hay saldo.
A10: Invitados
A11: Hay cuatro filas de ejemplo. Bórralas antes de usar la lista de verdad. Adultos más niños es el total de esa fila. Asisten copia el total solo cuando el RSVP es Confirmado. La lista cuadra cuando todas las personas tienen RSVP. El filtro de la primera fila sirve para ver, por ejemplo, solo pendientes.
A13: Mesas
A14: Numera las mesas y escribe su capacidad. En Invitados elige ese número. Apartados suma a quien no ha rechazado, para no soltar el lugar demasiado pronto. Confirmados cuenta solo los sí. Si Libres sale negativo, esa mesa está por encima de su capacidad.
A16: Menú
A17: Define qué se sirve en cada momento. Las porciones siguen a las personas confirmadas y, si aún no hay, a los invitados previstos. A la derecha está el conteo por tipo de menú. Comida, barra y pastel se pagan en Presupuesto, para no sumar dos veces el mismo gasto.
... A26: Cada hoja trae filas vacías con fórmulas. Cuando se acaben, copia la última fila y pégala debajo. En Excel también puedes insertar una fila en medio de la lista: las sumas se ajustan.

Sheet Listas
A1: Estas listas alimentan los menús desplegables. No hace falta editar esta hoja.
A2: Lugar | B2: Pendiente | C2: Novia | D2: No enviada | E2: Estándar | F2: Por cotizar | G2: Por contactar | H2: Por hacer | I2: Alta | J2: Sí | K2: 1
A3: Banquete | B3: Confirmado | C3: Novio | D3: Enviada | E3: Vegetariano | F3: Cotizado | G3: En conversación | H3: En curso | I3: Media | J3: No | K3: 2
A4: Bebidas | B4: Rechazado | C4: Ambos | D4: Entregada | E4: Vegano | F4: Apartado | G4: Cotizado | H4: Hecho | I4: Baja | K4: 3
A5: Pastel | C5: Otro | E5: Sin gluten | F5: Contratado | G5: Contratado | K5: 4
A6: Música | E6: Infantil | F6: Pagado parcial | G6: Descartado | K6: 5
A7: Foto y video | E7: Otro | F7: Pagado | K7: 6
A8: Flores y decoración | F8: Cancelado | K8: 7
A9: Invitaciones | K9: 8
A10: Vestuario | K10: 9
A11: Belleza | K11: 10
A12: Transporte | K12: 11
A13: Mobiliario | K13: 12
A14: Recuerdos | K14: 13
A15: Coordinación | K15: 14
A16: Otra | K16: 15
K17: 16
K18: 17
K19: 18
K20: 19
K21: 20
